<?xml version="1.0" ?>
<sdf version='1.7'>
  <world name='genis_hasta_odasi_fuel'>
    <light name='sun' type='directional'>
      <cast_shadows>1</cast_shadows>
      <pose>0 0 10 0 -0 0</pose>
      <diffuse>0.8 0.8 0.8 1</diffuse>
      <specular>0.2 0.2 0.2 1</specular>
      <attenuation>
        <range>1000</range>
        <constant>0.9</constant>
        <linear>0.01</linear>
        <quadratic>0.001</quadratic>
      </attenuation>
      <direction>-0.5 0.1 -0.9</direction>
      <spot>
        <inner_angle>0</inner_angle>
        <outer_angle>0</outer_angle>
        <falloff>0</falloff>
      </spot>
    </light>
    <model name='floor'>
      <static>1</static>
      <link name='floor_link'>
        <pose>0 0 0 0 -0 0</pose>
        <collision name='collision'>
          <geometry>
            <box>
              <size>8 6 0.01</size>
            </box>
          </geometry>
          <max_contacts>10</max_contacts>
          <surface>
            <contact>
              <ode/>
            </contact>
            <bounce/>
            <friction>
              <torsional>
                <ode/>
              </torsional>
              <ode/>
            </friction>
          </surface>
        </collision>
        <visual name='visual'>
          <geometry>
            <box>
              <size>8 6 0.01</size>
            </box>
          </geometry>
          <material>
            <script>
              <uri>file://media/materials/scripts/gazebo.material</uri>
              <name>Gazebo/Wood</name>
            </script>
          </material>
        </visual>
        <self_collide>0</self_collide>
        <enable_wind>0</enable_wind>
        <kinematic>0</kinematic>
      </link>
    </model>
    <model name='wall1'>
      <static>1</static>
      <link name='link'>
        <pose>0 3 1.25 0 -0 0</pose>
        <collision name='collision'>
          <geometry>
            <box>
              <size>8 0.1 2.5</size>
            </box>
          </geometry>
          <max_contacts>10</max_contacts>
          <surface>
            <contact>
              <ode/>
            </contact>
            <bounce/>
            <friction>
              <torsional>
                <ode/>
              </torsional>
              <ode/>
            </friction>
          </surface>
        </collision>
        <visual name='visual'>
          <geometry>
            <box>
              <size>8 0.1 2.5</size>
            </box>
          </geometry>
        </visual>
        <self_collide>0</self_collide>
        <enable_wind>0</enable_wind>
        <kinematic>0</kinematic>
      </link>
    </model>
    <model name='wall2'>
      <static>1</static>
      <link name='link'>
        <pose>0 -3 1.25 0 -0 0</pose>
        <collision name='collision'>
          <geometry>
            <box>
              <size>8 0.1 2.5</size>
            </box>
          </geometry>
          <max_contacts>10</max_contacts>
          <surface>
            <contact>
              <ode/>
            </contact>
            <bounce/>
            <friction>
              <torsional>
                <ode/>
              </torsional>
              <ode/>
            </friction>
          </surface>
        </collision>
        <visual name='visual'>
          <geometry>
            <box>
              <size>8 0.1 2.5</size>
            </box>
          </geometry>
        </visual>
        <self_collide>0</self_collide>
        <enable_wind>0</enable_wind>
        <kinematic>0</kinematic>
      </link>
    </model>
    <model name='wall3'>
      <static>1</static>
      <link name='link'>
        <pose>4 0 1.25 0 -0 0</pose>
        <collision name='collision'>
          <geometry>
            <box>
              <size>0.1 6 2.5</size>
            </box>
          </geometry>
          <max_contacts>10</max_contacts>
          <surface>
            <contact>
              <ode/>
            </contact>
            <bounce/>
            <friction>
              <torsional>
                <ode/>
              </torsional>
              <ode/>
            </friction>
          </surface>
        </collision>
        <visual name='visual'>
          <geometry>
            <box>
              <size>0.1 6 2.5</size>
            </box>
          </geometry>
        </visual>
        <self_collide>0</self_collide>
        <enable_wind>0</enable_wind>
        <kinematic>0</kinematic>
      </link>
    </model>
    <model name='wall4'>
      <static>1</static>
      <link name='link'>
        <pose>-4 0 1.25 0 -0 0</pose>
        <collision name='collision'>
          <geometry>
            <box>
              <size>0.1 6 2.5</size>
            </box>
          </geometry>
          <max_contacts>10</max_contacts>
          <surface>
            <contact>
              <ode/>
            </contact>
            <bounce/>
            <friction>
              <torsional>
                <ode/>
              </torsional>
              <ode/>
            </friction>
          </surface>
        </collision>
        <visual name='visual'>
          <geometry>
            <box>
              <size>0.1 6 2.5</size>
            </box>
          </geometry>
        </visual>
        <self_collide>0</self_collide>
        <enable_wind>0</enable_wind>
        <kinematic>0</kinematic>
      </link>
    </model>
    <model name='MalePatientBed'>
      <link name='link'>
        <pose>0 0 0 0 -0 0</pose>
        <visual name='visual'>
          <geometry>
            <mesh>
              <uri>model://MalePatientBed/meshes/MalePatientBed.obj</uri>
            </mesh>
          </geometry>
        </visual>
        <collision name='collision'>
          <geometry>
            <mesh>
              <uri>model://MalePatientBed/meshes/MalePatientBed.obj</uri>
            </mesh>
          </geometry>
          <max_contacts>10</max_contacts>
          <surface>
            <contact>
              <ode/>
            </contact>
            <bounce/>
            <friction>
              <torsional>
                <ode/>
              </torsional>
              <ode/>
            </friction>
          </surface>
        </collision>
        <self_collide>0</self_collide>
        <inertial>
          <pose>0 0 0 0 -0 0</pose>
          <inertia>
            <ixx>1</ixx>
            <ixy>0</ixy>
            <ixz>0</ixz>
            <iyy>1</iyy>
            <iyz>0</iyz>
            <izz>1</izz>
          </inertia>
          <mass>1</mass>
        </inertial>
        <enable_wind>0</enable_wind>
        <kinematic>0</kinematic>
      </link>
      <pose>0 0 0 0 -0 0</pose>
    </model>
    <model name='BPCart'>
      <link name='body'>
        <pose>0 0 0 0 -0 0</pose>
        <visual name='visual'>
          <geometry>
            <mesh>
              <uri>model://BPCart/meshes/Cart_BP.obj</uri>
            </mesh>
          </geometry>
        </visual>
        <collision name='collision'>
          <geometry>
            <mesh>
              <uri>model://BPCart/meshes/Cart_BP_Col.obj</uri>
            </mesh>
          </geometry>
          <max_contacts>10</max_contacts>
          <surface>
            <contact>
              <ode/>
            </contact>
            <bounce/>
            <friction>
              <torsional>
                <ode/>
              </torsional>
              <ode/>
            </friction>
          </surface>
        </collision>
        <self_collide>0</self_collide>
        <inertial>
          <pose>0 0 0 0 -0 0</pose>
          <inertia>
            <ixx>1</ixx>
            <ixy>0</ixy>
            <ixz>0</ixz>
            <iyy>1</iyy>
            <iyz>0</iyz>
            <izz>1</izz>
          </inertia>
          <mass>1</mass>
        </inertial>
        <enable_wind>0</enable_wind>
        <kinematic>0</kinematic>
      </link>
      <pose>1.5 0.8 0 0 -0 0</pose>
    </model>
    <model name='BedsideTable'>
      <link name='body'>
        <pose>0 0 0 0 0 -1.5708</pose>
        <visual name='visual'>
          <geometry>
            <mesh>
              <uri>model://BedsideTable/meshes/BedsideTable.obj</uri>
            </mesh>
          </geometry>
        </visual>
        <collision name='collision'>
          <geometry>
            <mesh>
              <uri>model://BedsideTable/meshes/BedsideTable_Col.obj</uri>
            </mesh>
          </geometry>
          <max_contacts>10</max_contacts>
          <surface>
            <contact>
              <ode/>
            </contact>
            <bounce/>
            <friction>
              <torsional>
                <ode/>
              </torsional>
              <ode/>
            </friction>
          </surface>
        </collision>
        <self_collide>0</self_collide>
        <inertial>
          <pose>0 0 0 0 -0 0</pose>
          <inertia>
            <ixx>1</ixx>
            <ixy>0</ixy>
            <ixz>0</ixz>
            <iyy>1</iyy>
            <iyz>0</iyz>
            <izz>1</izz>
          </inertia>
          <mass>1</mass>
        </inertial>
        <enable_wind>0</enable_wind>
        <kinematic>0</kinematic>
      </link>
      <pose>-1.5 0.8 0 0 -0 0</pose>
    </model>
    <model name='Chair'>
      <link name='body'>
        <pose>0 0 0 0 -0 1.5708</pose>
        <visual name='visual'>
          <geometry>
            <mesh>
              <uri>model://Chair/meshes/Chair.obj</uri>
              <scale>0.00817 0.00817 0.00817</scale>
            </mesh>
          </geometry>
        </visual>
        <collision name='collision'>
          <geometry>
            <mesh>
              <uri>model://Chair/meshes/Chair.obj</uri>
              <scale>0.00817 0.00817 0.00817</scale>
            </mesh>
          </geometry>
          <max_contacts>10</max_contacts>
          <surface>
            <contact>
              <ode/>
            </contact>
            <bounce/>
            <friction>
              <torsional>
                <ode/>
              </torsional>
              <ode/>
            </friction>
          </surface>
        </collision>
        <self_collide>0</self_collide>
        <inertial>
          <pose>0 0 0 0 -0 0</pose>
          <inertia>
            <ixx>1</ixx>
            <ixy>0</ixy>
            <ixz>0</ixz>
            <iyy>1</iyy>
            <iyz>0</iyz>
            <izz>1</izz>
          </inertia>
          <mass>1</mass>
        </inertial>
        <enable_wind>0</enable_wind>
        <kinematic>0</kinematic>
      </link>
      <pose>0 -2 0 0 -0 1.57</pose>
    </model>
    <gravity>0 0 -9.8</gravity>
    <magnetic_field>6e-06 2.3e-05 -4.2e-05</magnetic_field>
    <atmosphere type='adiabatic'/>
    <physics type='ode'>
      <max_step_size>0.001</max_step_size>
      <real_time_factor>1</real_time_factor>
      <real_time_update_rate>1000</real_time_update_rate>
    </physics>
    <scene>
      <ambient>0.4 0.4 0.4 1</ambient>
      <background>0.7 0.7 0.7 1</background>
      <shadows>1</shadows>
    </scene>
    <wind/>
    <spherical_coordinates>
      <surface_model>EARTH_WGS84</surface_model>
      <latitude_deg>0</latitude_deg>
      <longitude_deg>0</longitude_deg>
      <elevation>0</elevation>
      <heading_deg>0</heading_deg>
    </spherical_coordinates>
    <state world_name='genis_hasta_odasi_fuel'>
      <sim_time>1943 702000000</sim_time>
      <real_time>2343 810278756</real_time>
      <wall_time>1749330938 522311454</wall_time>
      <iterations>1165539</iterations>
      <model name='BPCart'>
        <pose>-3.03592 1.86848 0.008446 0 -0 1.33845</pose>
        <scale>1 1 1</scale>
        <link name='body'>
          <pose>-3.03592 1.86848 0.008446 0 -0 1.33845</pose>
          <velocity>0 0 0 0 -0 0</velocity>
          <acceleration>-0 -0 -0 0 -0 0</acceleration>
          <wrench>-0 -0 -0 0 -0 0</wrench>
        </link>
      </model>
      <model name='BedsideTable'>
        <pose>-3.46069 -0.969822 0.005173 -0 2e-06 0.00127</pose>
        <scale>1 1 1</scale>
        <link name='body'>
          <pose>-3.46069 -0.969822 0.005173 -2e-06 -0 -1.56953</pose>
          <velocity>0 0 0 0 -0 0</velocity>
          <acceleration>0 0 -9.8 0 -0 0</acceleration>
          <wrench>0 0 -9.8 0 -0 0</wrench>
        </link>
      </model>
      <model name='Chair'>
        <pose>-2.34492 2.34403 0.129769 -0.461361 0.005399 -1.57522</pose>
        <scale>1 1 1</scale>
        <link name='body'>
          <pose>-2.34492 2.34403 0.129769 0.006031 0.461354 -0.001734</pose>
          <velocity>0 0 0 0 -0 0</velocity>
          <acceleration>-1.00699 4.00735 -0.488405 1.83057 -0.266574 0.674905</acceleration>
          <wrench>-1.00699 4.00735 -0.488405 0 -0 0</wrench>
        </link>
      </model>
      <model name='FemaleVisitorSit'>
        <pose>-2.06472 2.32059 0.10291 0 -0 0</pose>
        <scale>1 1 1</scale>
        <link name='body'>
          <pose>-2.06472 2.32059 0.10291 0 -0 0</pose>
          <velocity>0 0 0 0 -0 0</velocity>
          <acceleration>0 0 0 0 -0 0</acceleration>
          <wrench>0 0 0 0 -0 0</wrench>
        </link>
      </model>
      <model name='HospitalRobot'>
        <pose>-0.405637 -2.11681 0.004999 0 2e-06 0.385191</pose>
        <scale>1 1 1</scale>
        <link name='body'>
          <pose>-0.405637 -2.11681 0.004999 0 2e-06 0.385191</pose>
          <velocity>-0.001773 -0.000715 -8e-06 -0.001891 0.004613 0.000605</velocity>
          <acceleration>1.43338 0.618196 0 -0.83898 0.19401 -3.13055</acceleration>
          <wrench>243.674 105.093 4e-06 0 -0 0</wrench>
        </link>
        <link name='suspension_tire_left'>
          <pose>-0.484541 -1.92219 0.06635 0 2e-06 0.385191</pose>
          <velocity>-0.00019 -7.9e-05 -0.005704 -0.001723 0.004196 0.000476</velocity>
          <acceleration>-1.56102 -0.63678 -0.000191 -0.30414 1.03363 2.8949</acceleration>
          <wrench>-1.56102 -0.63678 -0.000191 0 -0 0</wrench>
        </link>
        <link name='suspension_tire_right'>
          <pose>-0.326732 -2.31142 0.06635 0 2e-06 0.385191</pose>
          <velocity>-0.001663 -0.000674 -0.005703 -0.001734 0.004223 0.000762</velocity>
          <acceleration>-4.97443 -2.01704 0.000144 -0.325736 0.978997 -2.81666</acceleration>
          <wrench>-4.97443 -2.01704 0.000144 0 -0 0</wrench>
        </link>
        <link name='tire_left'>
          <pose>-0.48454 -1.92219 0.06635 0 0.278056 0.385191</pose>
          <velocity>0.000405 0.000165 -0.005704 -0.002787 0.006823 0.000477</velocity>
          <acceleration>-0.370457 -0.148165 -0.000184 0.696604 0.42696 -0.243928</acceleration>
          <wrench>-1.85229 -0.740823 -0.000919 0 -0 0</wrench>
        </link>
        <link name='tire_right'>
          <pose>-0.326731 -2.31142 0.06635 -3.14159 0.226601 -2.7564</pose>
          <velocity>0.000641 0.000261 -0.005703 -0.004349 0.010675 0.000767</velocity>
          <acceleration>-0.36531 -0.146084 0.000188 0.683429 0.529989 0.334528</acceleration>
          <wrench>-1.82655 -0.73042 0.00094 0 -0 0</wrench>
        </link>
      </model>
      <model name='MalePatientBed'>
        <pose>-2.82795 0.97491 0.00666 -1e-06 -0 -0.020499</pose>
        <scale>1 1 1</scale>
        <link name='link'>
          <pose>-2.82795 0.97491 0.00666 -1e-06 -0 -0.020499</pose>
          <velocity>0 0 0 0 -0 0</velocity>
          <acceleration>0.000185 0.006772 0.199467 2.20459 0.111275 0</acceleration>
          <wrench>0.000185 0.006772 0.199467 0 -0 0</wrench>
        </link>
      </model>
      <model name='Nurse'>
        <pose>-2.69692 -0.220683 0 0 -0 0.912198</pose>
        <scale>1 1 1</scale>
        <link name='body'>
          <pose>-2.69692 -0.220683 0 0 -0 0.912198</pose>
          <velocity>0 0 0 0 -0 0</velocity>
          <acceleration>0 0 0 0 -0 0</acceleration>
          <wrench>0 0 0 0 -0 0</wrench>
        </link>
      </model>
      <model name='aws_robomaker_residential_Refrigerator_01'>
        <pose>3.17662 2.4289 0 0 -0 0</pose>
        <scale>1 1 1</scale>
        <link name='link'>
          <pose>3.17662 2.4289 0 0 -0 0</pose>
          <velocity>0 0 0 0 -0 0</velocity>
          <acceleration>0 0 0 0 -0 0</acceleration>
          <wrench>0 0 0 0 -0 0</wrench>
        </link>
      </model>
      <model name='aws_robomaker_residential_SofaB_01'>
        <pose>-2.89766 -2.47741 0.005 0 -0 1.64116</pose>
        <scale>1 1 1</scale>
        <link name='link'>
          <pose>-2.89766 -2.47741 0.005 0 -0 1.64116</pose>
          <velocity>0 0 0 0 -0 0</velocity>
          <acceleration>0 -0 0.000453 -0.002849 -0.002087 0</acceleration>
          <wrench>0 -0 0.032853 0 -0 0</wrench>
        </link>
      </model>
      <model name='aws_robomaker_residential_Sofa_01'>
        <pose>-4.26406 -6.96235 -6.27546e+06 0 -0 0</pose>
        <scale>1 1 1</scale>
        <link name='link'>
          <pose>-4.26406 -6.96235 -6.27546e+06 0 -0 0</pose>
          <velocity>0 0 -11090.5 0 -0 0</velocity>
          <acceleration>0 0 -9.8 0 -0 0</acceleration>
          <wrench>0 0 -710.5 0 -0 0</wrench>
        </link>
      </model>
      <model name='aws_robomaker_residential_Sofa_01_0'>
        <pose>-0.023815 -5.40651 -6.2572e+06 0 -0 0</pose>
        <scale>1 1 1</scale>
        <link name='link'>
          <pose>-0.023815 -5.40651 -6.2572e+06 0 -0 0</pose>
          <velocity>0 0 -11074.4 0 -0 0</velocity>
          <acceleration>0 0 -9.8 0 -0 0</acceleration>
          <wrench>0 0 -710.5 0 -0 0</wrench>
        </link>
      </model>
      <model name='floor'>
        <pose>-0.068136 -0.022705 0 0 -0 0</pose>
        <scale>1 1 1</scale>
        <link name='floor_link'>
          <pose>-0.068136 -0.022705 0 0 -0 0</pose>
          <velocity>0 0 0 0 -0 0</velocity>
          <acceleration>0 0 0 0 -0 0</acceleration>
          <wrench>0 0 0 0 -0 0</wrench>
        </link>
      </model>
      <model name='kgeu_sim'>
        <pose>-6.3411 6.95318 -680002 -0 -0 -0</pose>
        <scale>1 1 1</scale>
        <link name='base_footprint'>
          <pose>-6.3411 6.95318 -680002 -0 -0 -0</pose>
          <velocity>-0 -0 -3650.75 0 -0 0</velocity>
          <acceleration>-0 -0 -9.8 0 -0 0</acceleration>
          <wrench>-0 -0 -3724 0 -0 0</wrench>
        </link>
        <link name='l_wheel_left_back'>
          <pose>-6.92899 7.52839 -680002 1.5708 -0 -3.14159</pose>
          <velocity>0 0 -3650.75 0 -0 0</velocity>
          <acceleration>-0 0 -9.8 0 -0 0</acceleration>
          <wrench>-0 0 -147 0 -0 0</wrench>
        </link>
        <link name='l_wheel_left_front'>
          <pose>-6.31948 7.52839 -680002 1.5708 -0 -3.14159</pose>
          <velocity>0 -0 -3650.75 0 -0 0</velocity>
          <acceleration>-0 0 -9.8 0 -0 0</acceleration>
          <wrench>-0 0 -147 0 -0 0</wrench>
        </link>
        <link name='l_wheel_right_back'>
          <pose>-6.92899 6.37465 -680002 1.5708 -0 0</pose>
          <velocity>0 0 -3650.75 0 -0 0</velocity>
          <acceleration>0 0 -9.8 0 -0 0</acceleration>
          <wrench>0 0 -147 0 -0 0</wrench>
        </link>
        <link name='l_wheel_right_front'>
          <pose>-6.31948 6.37465 -680002 1.5708 -0 0</pose>
          <velocity>0 -0 -3650.75 0 -0 0</velocity>
          <acceleration>0 0 -9.8 0 -0 0</acceleration>
          <wrench>0 0 -147 0 -0 0</wrench>
        </link>
      </model>
      <model name='wall1'>
        <pose>0 0 0 0 -0 0</pose>
        <scale>1 1 1</scale>
        <link name='link'>
          <pose>0 3 1.25 0 -0 0</pose>
          <velocity>0 0 0 0 -0 0</velocity>
          <acceleration>0 0 0 0 -0 0</acceleration>
          <wrench>0 0 0 0 -0 0</wrench>
        </link>
      </model>
      <model name='wall2'>
        <pose>0 0 0 0 -0 0</pose>
        <scale>1 1 1</scale>
        <link name='link'>
          <pose>0 -3 1.25 0 -0 0</pose>
          <velocity>0 0 0 0 -0 0</velocity>
          <acceleration>0 0 0 0 -0 0</acceleration>
          <wrench>0 0 0 0 -0 0</wrench>
        </link>
      </model>
      <model name='wall3'>
        <pose>0 0 0 0 -0 0</pose>
        <scale>1 1 1</scale>
        <link name='link'>
          <pose>4 0 1.25 0 -0 0</pose>
          <velocity>0 0 0 0 -0 0</velocity>
          <acceleration>0 0 0 0 -0 0</acceleration>
          <wrench>0 0 0 0 -0 0</wrench>
        </link>
      </model>
      <model name='wall4'>
        <pose>-0.04458 -0.026834 0 0 -0 0</pose>
        <scale>1 1 1</scale>
        <link name='link'>
          <pose>-4.04458 -0.026834 1.25 0 -0 0</pose>
          <velocity>0 0 0 0 -0 0</velocity>
          <acceleration>0 0 0 0 -0 0</acceleration>
          <wrench>0 0 0 0 -0 0</wrench>
        </link>
      </model>
      <light name='sun'>
        <pose>0 0 10 0 -0 0</pose>
      </light>
    </state>
    <gui fullscreen='0'>
      <camera name='user_camera'>
        <pose>10.4005 -0.037188 7.25877 0 0.461955 2.98828</pose>
        <view_controller>orbit</view_controller>
        <projection_type>perspective</projection_type>
      </camera>
    </gui>
    <model name='aws_robomaker_residential_Sofa_01'>
      <link name='link'>
        <inertial>
          <mass>72.5</mass>
          <pose>0 0 0 0 -0 0</pose>
          <inertia>
            <ixx>1</ixx>
            <ixy>0</ixy>
            <ixz>0</ixz>
            <iyy>1</iyy>
            <iyz>0</iyz>
            <izz>1</izz>
          </inertia>
        </inertial>
        <collision name='collision'>
          <geometry>
            <mesh>
              <uri>model://aws_robomaker_residential_Sofa_01/meshes/aws_Sofa_01_collision.DAE</uri>
              <scale>1 1 1</scale>
            </mesh>
          </geometry>
          <max_contacts>10</max_contacts>
          <surface>
            <contact>
              <ode/>
            </contact>
            <bounce/>
            <friction>
              <torsional>
                <ode/>
              </torsional>
              <ode/>
            </friction>
          </surface>
        </collision>
        <visual name='visual'>
          <geometry>
            <mesh>
              <uri>model://aws_robomaker_residential_Sofa_01/meshes/aws_Sofa_01_visual.DAE</uri>
            </mesh>
          </geometry>
          <meta>
            <layer>1</layer>
          </meta>
        </visual>
        <self_collide>0</self_collide>
        <enable_wind>0</enable_wind>
        <kinematic>0</kinematic>
      </link>
      <pose>-4.26406 -6.96235 0 0 -0 0</pose>
    </model>
    <model name='aws_robomaker_residential_Sofa_01_0'>
      <link name='link'>
        <inertial>
          <mass>72.5</mass>
          <pose>0 0 0 0 -0 0</pose>
          <inertia>
            <ixx>1</ixx>
            <ixy>0</ixy>
            <ixz>0</ixz>
            <iyy>1</iyy>
            <iyz>0</iyz>
            <izz>1</izz>
          </inertia>
        </inertial>
        <collision name='collision'>
          <geometry>
            <mesh>
              <uri>model://aws_robomaker_residential_Sofa_01/meshes/aws_Sofa_01_collision.DAE</uri>
              <scale>1 1 1</scale>
            </mesh>
          </geometry>
          <max_contacts>10</max_contacts>
          <surface>
            <contact>
              <ode/>
            </contact>
            <bounce/>
            <friction>
              <torsional>
                <ode/>
              </torsional>
              <ode/>
            </friction>
          </surface>
        </collision>
        <visual name='visual'>
          <geometry>
            <mesh>
              <uri>model://aws_robomaker_residential_Sofa_01/meshes/aws_Sofa_01_visual.DAE</uri>
            </mesh>
          </geometry>
          <meta>
            <layer>1</layer>
          </meta>
        </visual>
        <self_collide>0</self_collide>
        <enable_wind>0</enable_wind>
        <kinematic>0</kinematic>
      </link>
      <pose>-0.023815 -5.40651 0 0 -0 0</pose>
    </model>
    <model name='aws_robomaker_residential_SofaB_01'>
      <link name='link'>
        <inertial>
          <mass>72.5</mass>
          <pose>0 0 0 0 -0 0</pose>
          <inertia>
            <ixx>1</ixx>
            <ixy>0</ixy>
            <ixz>0</ixz>
            <iyy>1</iyy>
            <iyz>0</iyz>
            <izz>1</izz>
          </inertia>
        </inertial>
        <collision name='collision'>
          <geometry>
            <mesh>
              <uri>model://aws_robomaker_residential_SofaB_01/meshes/aws_SofaB_01_collision.DAE</uri>
              <scale>1 1 1</scale>
            </mesh>
          </geometry>
          <max_contacts>10</max_contacts>
          <surface>
            <contact>
              <ode/>
            </contact>
            <bounce/>
            <friction>
              <torsional>
                <ode/>
              </torsional>
              <ode/>
            </friction>
          </surface>
        </collision>
        <visual name='visual'>
          <geometry>
            <mesh>
              <uri>model://aws_robomaker_residential_SofaB_01/meshes/aws_SofaB_01_visual.DAE</uri>
            </mesh>
          </geometry>
          <meta>
            <layer>1</layer>
          </meta>
        </visual>
        <self_collide>0</self_collide>
        <enable_wind>0</enable_wind>
        <kinematic>0</kinematic>
      </link>
      <pose>-2.91905 -2.31069 0 0 -0 0</pose>
    </model>
    <model name='aws_robomaker_residential_Refrigerator_01'>
      <link name='link'>
        <inertial>
          <mass>1</mass>
        </inertial>
        <collision name='collision'>
          <geometry>
            <mesh>
              <uri>model://aws_robomaker_residential_Refrigerator_01/meshes/aws_Refrigerator_01_collision.DAE</uri>
              <scale>1 1 1</scale>
            </mesh>
          </geometry>
          <max_contacts>10</max_contacts>
          <surface>
            <contact>
              <ode/>
            </contact>
            <bounce/>
            <friction>
              <torsional>
                <ode/>
              </torsional>
              <ode/>
            </friction>
          </surface>
        </collision>
        <visual name='visual'>
          <geometry>
            <mesh>
              <uri>model://aws_robomaker_residential_Refrigerator_01/meshes/aws_Refrigerator_01_visual.DAE</uri>
            </mesh>
          </geometry>
          <meta>
            <layer>1</layer>
          </meta>
        </visual>
        <self_collide>0</self_collide>
        <enable_wind>0</enable_wind>
        <kinematic>0</kinematic>
      </link>
      <static>1</static>
      <pose>-0.724411 2.36531 0 0 -0 0</pose>
    </model>
    <model name='HospitalRobot'>
      <plugin name='slotcar' filename='libslotcar.so'>
        <nominal_drive_speed>0.7</nominal_drive_speed>
        <nominal_drive_acceleration>0.5</nominal_drive_acceleration>
        <max_drive_acceleration>0.75</max_drive_acceleration>
        <nominal_turn_speed>0.3</nominal_turn_speed>
        <nominal_turn_acceleration>1.5</nominal_turn_acceleration>
        <max_turn_acceleration>2.0</max_turn_acceleration>
        <stop_distance>0.75</stop_distance>
        <stop_radius>0.75</stop_radius>
        <reversible>0</reversible>
        <nominal_voltage>24.0</nominal_voltage>
        <nominal_capacity>24.0</nominal_capacity>
        <charging_current>5.0</charging_current>
        <mass>70.0</mass>
        <inertia>40.0</inertia>
        <friction_coefficient>0.22</friction_coefficient>
        <nominal_power>20.0</nominal_power>
      </plugin>
      <link name='body'>
        <pose>0 0 0 0 -0 0</pose>
        <inertial>
          <pose>0 0 0.693 0 -0 0</pose>
          <mass>170</mass>
          <inertia>
            <ixx>34.6605</ixx>
            <iyy>32.8369</iyy>
            <izz>13.0691</izz>
            <ixy>0</ixy>
            <ixz>0</ixz>
            <iyz>0</iyz>
          </inertia>
        </inertial>
        <collision name='collision'>
          <pose>0 0 0.7 0 -0 0</pose>
          <geometry>
            <box>
              <size>0.7 0.7 1.4</size>
            </box>
          </geometry>
          <surface>
            <friction>
              <torsional>
                <coefficient>0</coefficient>
                <ode/>
              </torsional>
              <ode>
                <mu>0</mu>
                <mu2>0</mu2>
              </ode>
              <bullet>
                <friction>0</friction>
                <friction2>0</friction2>
                <rolling_friction>0</rolling_friction>
              </bullet>
            </friction>
            <contact>
              <ode/>
            </contact>
            <bounce/>
          </surface>
          <max_contacts>10</max_contacts>
        </collision>
        <visual name='visual'>
          <geometry>
            <mesh>
              <uri>https://fuel.gazebosim.org/1.0/deneme1/models/hospitalrobot/1/files/meshes/HospitalRobot.obj</uri>
            </mesh>
          </geometry>
        </visual>
        <visual name='front_wheel_left'>
          <pose>0.17 -0.21 0.03 0 -0 0</pose>
          <geometry>
            <mesh>
              <uri>https://fuel.gazebosim.org/1.0/deneme1/models/hospitalrobot/1/files/meshes/SmallWheel.obj</uri>
            </mesh>
          </geometry>
        </visual>
        <visual name='back_wheel_left'>
          <pose>-0.24 -0.21 0.03 0 -0 0</pose>
          <geometry>
            <mesh>
              <uri>https://fuel.gazebosim.org/1.0/deneme1/models/hospitalrobot/1/files/meshes/SmallWheel.obj</uri>
            </mesh>
          </geometry>
        </visual>
        <visual name='front_wheel_right'>
          <pose>0.17 0.21 0.03 0 -0 0</pose>
          <geometry>
            <mesh>
              <uri>https://fuel.gazebosim.org/1.0/deneme1/models/hospitalrobot/1/files/meshes/SmallWheel.obj</uri>
            </mesh>
          </geometry>
        </visual>
        <visual name='back_wheel_right'>
          <pose>-0.24 0.21 0.03 0 -0 0</pose>
          <geometry>
            <mesh>
              <uri>https://fuel.gazebosim.org/1.0/deneme1/models/hospitalrobot/1/files/meshes/SmallWheel.obj</uri>
            </mesh>
          </geometry>
        </visual>
        <self_collide>0</self_collide>
        <enable_wind>0</enable_wind>
        <kinematic>0</kinematic>
      </link>
      <link name='suspension_tire_left'>
        <pose>0 0.21 0.06 0 -0 0</pose>
        <inertial>
          <mass>1</mass>
          <inertia>
            <ixx>1</ixx>
            <iyy>1</iyy>
            <izz>1</izz>
            <ixy>0</ixy>
            <ixz>0</ixz>
            <iyz>0</iyz>
          </inertia>
          <pose>0 0 0 0 -0 0</pose>
        </inertial>
        <self_collide>0</self_collide>
        <enable_wind>0</enable_wind>
        <kinematic>0</kinematic>
      </link>
      <joint name='joint_suspension_tire_left' type='prismatic'>
        <parent>body</parent>
        <child>suspension_tire_left</child>
        <axis>
          <xyz>0 0 1</xyz>
          <dynamics>
            <damping>500</damping>
            <spring_reference>-0.05</spring_reference>
            <spring_stiffness>2000</spring_stiffness>
          </dynamics>
          <limit>
            <lower>-1e+16</lower>
            <upper>1e+16</upper>
          </limit>
        </axis>
        <physics>
          <ode>
            <implicit_spring_damper>1</implicit_spring_damper>
            <limit>
              <cfm>0</cfm>
              <erp>0.2</erp>
            </limit>
          </ode>
        </physics>
      </joint>
      <link name='tire_left'>
        <pose>0 0.21 0.06 0 -0 0</pose>
        <inertial>
          <pose>0 0 0 0 -0 0</pose>
          <mass>5</mass>
          <inertia>
            <ixx>0.757897</ixx>
            <iyy>1.30298</iyy>
            <izz>0.757897</izz>
            <ixy>0</ixy>
            <ixz>0</ixz>
            <iyz>0</iyz>
          </inertia>
        </inertial>
        <visual name='fat_wheel_left'>
          <geometry>
            <mesh>
              <uri>https://fuel.gazebosim.org/1.0/deneme1/models/hospitalrobot/1/files/meshes/FatWheel.obj</uri>
            </mesh>
          </geometry>
        </visual>
        <collision name='tire_left'>
          <geometry>
            <sphere>
              <radius>0.06137</radius>
            </sphere>
          </geometry>
          <surface>
            <contact>
              <ode>
                <kp>1e+07</kp>
                <kd>1</kd>
              </ode>
            </contact>
            <bounce/>
            <friction>
              <torsional>
                <ode/>
              </torsional>
              <ode/>
            </friction>
          </surface>
          <max_contacts>10</max_contacts>
        </collision>
        <self_collide>0</self_collide>
        <enable_wind>0</enable_wind>
        <kinematic>0</kinematic>
      </link>
      <joint name='joint_tire_left' type='revolute'>
        <parent>suspension_tire_left</parent>
        <child>tire_left</child>
        <axis>
          <xyz>0 1 0</xyz>
          <limit>
            <lower>-1e+16</lower>
            <upper>1e+16</upper>
          </limit>
          <dynamics>
            <spring_reference>0</spring_reference>
            <spring_stiffness>0</spring_stiffness>
          </dynamics>
        </axis>
      </joint>
      <link name='suspension_tire_right'>
        <pose>0 -0.21 0.06 0 -0 0</pose>
        <inertial>
          <mass>1</mass>
          <inertia>
            <ixx>1</ixx>
            <iyy>1</iyy>
            <izz>1</izz>
            <ixy>0</ixy>
            <ixz>0</ixz>
            <iyz>0</iyz>
          </inertia>
          <pose>0 0 0 0 -0 0</pose>
        </inertial>
        <self_collide>0</self_collide>
        <enable_wind>0</enable_wind>
        <kinematic>0</kinematic>
      </link>
      <joint name='joint_suspension_tire_right' type='prismatic'>
        <parent>body</parent>
        <child>suspension_tire_right</child>
        <axis>
          <xyz>0 0 1</xyz>
          <dynamics>
            <damping>500</damping>
            <spring_reference>-0.05</spring_reference>
            <spring_stiffness>2000</spring_stiffness>
          </dynamics>
          <limit>
            <lower>-1e+16</lower>
            <upper>1e+16</upper>
          </limit>
        </axis>
        <physics>
          <ode>
            <implicit_spring_damper>1</implicit_spring_damper>
            <limit>
              <cfm>0</cfm>
              <erp>0.2</erp>
            </limit>
          </ode>
        </physics>
      </joint>
      <link name='tire_right'>
        <pose>0 -0.21 0.06 0 -0 0</pose>
        <inertial>
          <pose>0 0 0 0 -0 0</pose>
          <mass>5</mass>
          <inertia>
            <ixx>0.757897</ixx>
            <iyy>1.30298</iyy>
            <izz>0.757897</izz>
            <ixy>0</ixy>
            <ixz>0</ixz>
            <iyz>0</iyz>
          </inertia>
        </inertial>
        <visual name='fat_wheel_right'>
          <geometry>
            <mesh>
              <uri>https://fuel.gazebosim.org/1.0/deneme1/models/hospitalrobot/1/files/meshes/FatWheel.obj</uri>
            </mesh>
          </geometry>
        </visual>
        <collision name='tire_right'>
          <geometry>
            <sphere>
              <radius>0.06137</radius>
            </sphere>
          </geometry>
          <surface>
            <contact>
              <ode>
                <kp>1e+07</kp>
                <kd>1</kd>
              </ode>
            </contact>
            <bounce/>
            <friction>
              <torsional>
                <ode/>
              </torsional>
              <ode/>
            </friction>
          </surface>
          <max_contacts>10</max_contacts>
        </collision>
        <self_collide>0</self_collide>
        <enable_wind>0</enable_wind>
        <kinematic>0</kinematic>
      </link>
      <joint name='joint_tire_right' type='revolute'>
        <parent>suspension_tire_right</parent>
        <child>tire_right</child>
        <axis>
          <xyz>0 1 0</xyz>
          <limit>
            <lower>-1e+16</lower>
            <upper>1e+16</upper>
          </limit>
          <dynamics>
            <spring_reference>0</spring_reference>
            <spring_stiffness>0</spring_stiffness>
          </dynamics>
        </axis>
      </joint>
      <pose>-0.876768 -2.06663 0 0 -0 0</pose>
    </model>
    <model name='Nurse'>
      <static>1</static>
      <link name='body'>
        <pose>0 0 0 0 -0 0</pose>
        <visual name='visual'>
          <geometry>
            <mesh>
              <uri>https://fuel.gazebosim.org/1.0/openrobotics/models/nurse/2/files/meshes/Nurse.obj</uri>
            </mesh>
          </geometry>
        </visual>
        <collision name='collision'>
          <geometry>
            <mesh>
              <uri>https://fuel.gazebosim.org/1.0/openrobotics/models/nurse/2/files/meshes/Nurse_Col.obj</uri>
            </mesh>
          </geometry>
          <max_contacts>10</max_contacts>
          <surface>
            <contact>
              <ode/>
            </contact>
            <bounce/>
            <friction>
              <torsional>
                <ode/>
              </torsional>
              <ode/>
            </friction>
          </surface>
        </collision>
        <self_collide>0</self_collide>
        <enable_wind>0</enable_wind>
        <kinematic>0</kinematic>
      </link>
      <pose>-2.69692 -0.220683 0 0 -0 0</pose>
    </model>
    <model name='FemaleVisitorSit'>
      <static>1</static>
      <link name='body'>
        <pose>0 0 0 0 -0 0</pose>
        <visual name='visual'>
          <geometry>
            <mesh>
              <uri>https://fuel.gazebosim.org/1.0/openrobotics/models/femalevisitorsit/2/files/meshes/FemaleVisitorSit.obj</uri>
            </mesh>
          </geometry>
        </visual>
        <collision name='collision'>
          <geometry>
            <mesh>
              <uri>https://fuel.gazebosim.org/1.0/openrobotics/models/femalevisitorsit/2/files/meshes/FemaleVisitorSit_Col.obj</uri>
            </mesh>
          </geometry>
          <max_contacts>10</max_contacts>
          <surface>
            <contact>
              <ode/>
            </contact>
            <bounce/>
            <friction>
              <torsional>
                <ode/>
              </torsional>
              <ode/>
            </friction>
          </surface>
        </collision>
        <self_collide>0</self_collide>
        <enable_wind>0</enable_wind>
        <kinematic>0</kinematic>
      </link>
      <pose>-2.35504 2.34709 0 0 -0 0</pose>
    </model>
    <model name='kgeu_sim'>
      <link name='base_footprint'>
        <inertial>
          <pose>-0.21102 -0.004151 -0.012986 0 -0 0</pose>
          <mass>380</mass>
          <inertia>
            <ixx>269.415</ixx>
            <ixy>-0.869112</ixy>
            <ixz>-21.8211</ixz>
            <iyy>344.627</iyy>
            <iyz>2.80293</iyz>
            <izz>450.994</izz>
          </inertia>
        </inertial>
        <collision name='base_footprint_fixed_joint_lump__base_link_collision'>
          <pose>0 0 0.001 0 -0 0</pose>
          <geometry>
            <mesh>
              <scale>1 1 1</scale>
              <uri>model://meshes/visual/base_link.STL</uri>
            </mesh>
          </geometry>
          <max_contacts>10</max_contacts>
          <surface>
            <contact>
              <ode/>
            </contact>
            <bounce/>
            <friction>
              <torsional>
                <ode/>
              </torsional>
              <ode/>
            </friction>
          </surface>
        </collision>
        <collision name='base_footprint_fixed_joint_lump__l_engine_left_back_collision_1'>
          <pose>-0.58789 0.44933 -0.18125 1.5708 -0 -3.14159</pose>
          <geometry>
            <mesh>
              <scale>1 1 1</scale>
              <uri>model://meshes/visual/l_engine_left_back.STL</uri>
            </mesh>
          </geometry>
          <max_contacts>10</max_contacts>
          <surface>
            <contact>
              <ode/>
            </contact>
            <bounce/>
            <friction>
              <torsional>
                <ode/>
              </torsional>
              <ode/>
            </friction>
          </surface>
        </collision>
        <collision name='base_footprint_fixed_joint_lump__l_engine_left_front_collision_2'>
          <pose>0.021624 0.44933 -0.18125 1.5708 -0 -3.14159</pose>
          <geometry>
            <mesh>
              <scale>1 1 1</scale>
              <uri>model://meshes/visual/l_engine_left_front.STL</uri>
            </mesh>
          </geometry>
          <max_contacts>10</max_contacts>
          <surface>
            <contact>
              <ode/>
            </contact>
            <bounce/>
            <friction>
              <torsional>
                <ode/>
              </torsional>
              <ode/>
            </friction>
          </surface>
        </collision>
        <collision name='base_footprint_fixed_joint_lump__l_engine_right_back_collision_3'>
          <pose>-0.45797 -0.55765 -0.10897 1.5708 -0 0</pose>
          <geometry>
            <mesh>
              <scale>1 1 1</scale>
              <uri>model://meshes/visual/l_engine_right_back.STL</uri>
            </mesh>
          </geometry>
          <max_contacts>10</max_contacts>
          <surface>
            <contact>
              <ode/>
            </contact>
            <bounce/>
            <friction>
              <torsional>
                <ode/>
              </torsional>
              <ode/>
            </friction>
          </surface>
        </collision>
        <collision name='base_footprint_fixed_joint_lump__l_engine_right_front_collision_4'>
          <pose>0.021624 -0.45265 -0.18125 1.5708 -0 0</pose>
          <geometry>
            <mesh>
              <scale>1 1 1</scale>
              <uri>model://meshes/visual/l_engine_right_front.STL</uri>
            </mesh>
          </geometry>
          <max_contacts>10</max_contacts>
          <surface>
            <contact>
              <ode/>
            </contact>
            <bounce/>
            <friction>
              <torsional>
                <ode/>
              </torsional>
              <ode/>
            </friction>
          </surface>
        </collision>
        <visual name='base_footprint_visual'>
          <pose>0 0 0 0 -0 0</pose>
          <geometry>
            <box>
              <size>0.001 0.001 0.001</size>
            </box>
          </geometry>
        </visual>
        <visual name='base_footprint_fixed_joint_lump__base_link_visual_1'>
          <pose>0 0 0.001 0 -0 0</pose>
          <geometry>
            <mesh>
              <scale>1 1 1</scale>
              <uri>model://meshes/visual/base_link.STL</uri>
            </mesh>
          </geometry>
        </visual>
        <visual name='base_footprint_fixed_joint_lump__l_engine_left_back_visual_2'>
          <pose>-0.58789 0.44933 -0.18125 1.5708 -0 -3.14159</pose>
          <geometry>
            <mesh>
              <scale>1 1 1</scale>
              <uri>model://meshes/visual/l_engine_left_back.STL</uri>
            </mesh>
          </geometry>
        </visual>
        <visual name='base_footprint_fixed_joint_lump__l_engine_left_front_visual_3'>
          <pose>0.021624 0.44933 -0.18125 1.5708 -0 -3.14159</pose>
          <geometry>
            <mesh>
              <scale>1 1 1</scale>
              <uri>model://meshes/visual/l_engine_left_front.STL</uri>
            </mesh>
          </geometry>
        </visual>
        <visual name='base_footprint_fixed_joint_lump__l_engine_right_back_visual_4'>
          <pose>-0.45797 -0.55765 -0.10897 1.5708 -0 0</pose>
          <geometry>
            <mesh>
              <scale>1 1 1</scale>
              <uri>model://meshes/visual/l_engine_right_back.STL</uri>
            </mesh>
          </geometry>
        </visual>
        <visual name='base_footprint_fixed_joint_lump__l_engine_right_front_visual_5'>
          <pose>0.021624 -0.45265 -0.18125 1.5708 -0 0</pose>
          <geometry>
            <mesh>
              <scale>1 1 1</scale>
              <uri>model://meshes/visual/l_engine_right_front.STL</uri>
            </mesh>
          </geometry>
        </visual>
        <self_collide>0</self_collide>
        <enable_wind>0</enable_wind>
        <kinematic>0</kinematic>
      </link>
      <joint name='j_engine_left_back' type='revolute'>
        <pose relative_to='base_footprint'>-0.587891 0.57521 -0.05133 1.5708 -0 -3.14159</pose>
        <parent>base_footprint</parent>
        <child>l_wheel_left_back</child>
        <axis>
          <xyz>0 0 1</xyz>
          <limit>
            <lower>-1e+16</lower>
            <upper>1e+16</upper>
          </limit>
          <dynamics>
            <spring_reference>0</spring_reference>
            <spring_stiffness>0</spring_stiffness>
          </dynamics>
        </axis>
      </joint>
      <link name='l_wheel_left_back'>
        <pose relative_to='j_engine_left_back'>0 0 0 0 -0 0</pose>
        <inertial>
          <pose>-6e-06 0.000159 0.11381 0 -0 0</pose>
          <mass>15</mass>
          <inertia>
            <ixx>0.58617</ixx>
            <ixy>-4.371e-05</ixy>
            <ixz>-4.3139e-06</ixz>
            <iyy>0.58725</iyy>
            <iyz>-5.3239e-05</iyz>
            <izz>0.97459</izz>
          </inertia>
        </inertial>
        <collision name='l_wheel_left_back_collision'>
          <pose>0 0 0 0 -0 0</pose>
          <geometry>
            <mesh>
              <scale>1 1 1</scale>
              <uri>model://meshes/visual/l_wheel_left_back.STL</uri>
            </mesh>
          </geometry>
          <max_contacts>10</max_contacts>
          <surface>
            <contact>
              <ode/>
            </contact>
            <bounce/>
            <friction>
              <torsional>
                <ode/>
              </torsional>
              <ode/>
            </friction>
          </surface>
        </collision>
        <visual name='l_wheel_left_back_visual'>
          <pose>0 0 0 0 -0 0</pose>
          <geometry>
            <mesh>
              <scale>1 1 1</scale>
              <uri>model://meshes/visual/l_wheel_left_back.STL</uri>
            </mesh>
          </geometry>
        </visual>
        <self_collide>0</self_collide>
        <enable_wind>0</enable_wind>
        <kinematic>0</kinematic>
      </link>
      <joint name='j_engine_left_front' type='revolute'>
        <pose relative_to='base_footprint'>0.021623 0.57521 -0.05133 1.5708 -0 -3.14159</pose>
        <parent>base_footprint</parent>
        <child>l_wheel_left_front</child>
        <axis>
          <xyz>0 0 1</xyz>
          <limit>
            <lower>-1e+16</lower>
            <upper>1e+16</upper>
          </limit>
          <dynamics>
            <spring_reference>0</spring_reference>
            <spring_stiffness>0</spring_stiffness>
          </dynamics>
        </axis>
      </joint>
      <link name='l_wheel_left_front'>
        <pose relative_to='j_engine_left_front'>0 0 0 0 -0 0</pose>
        <inertial>
          <pose>-6e-06 0.000159 0.11381 0 -0 0</pose>
          <mass>15</mass>
          <inertia>
            <ixx>0.58617</ixx>
            <ixy>-4.371e-05</ixy>
            <ixz>-4.3139e-06</ixz>
            <iyy>0.58725</iyy>
            <iyz>-5.3239e-05</iyz>
            <izz>0.97459</izz>
          </inertia>
        </inertial>
        <collision name='l_wheel_left_front_collision'>
          <pose>0 0 0 0 -0 0</pose>
          <geometry>
            <mesh>
              <scale>1 1 1</scale>
              <uri>model://meshes/visual/l_wheel_left_front.STL</uri>
            </mesh>
          </geometry>
          <max_contacts>10</max_contacts>
          <surface>
            <contact>
              <ode/>
            </contact>
            <bounce/>
            <friction>
              <torsional>
                <ode/>
              </torsional>
              <ode/>
            </friction>
          </surface>
        </collision>
        <visual name='l_wheel_left_front_visual'>
          <pose>0 0 0 0 -0 0</pose>
          <geometry>
            <mesh>
              <scale>1 1 1</scale>
              <uri>model://meshes/visual/l_wheel_left_front.STL</uri>
            </mesh>
          </geometry>
        </visual>
        <self_collide>0</self_collide>
        <enable_wind>0</enable_wind>
        <kinematic>0</kinematic>
      </link>
      <joint name='j_engine_right_back' type='revolute'>
        <pose relative_to='base_footprint'>-0.58789 -0.57853 -0.051326 1.5708 -0 0</pose>
        <parent>base_footprint</parent>
        <child>l_wheel_right_back</child>
        <axis>
          <xyz>0 0 1</xyz>
          <limit>
            <lower>-1e+16</lower>
            <upper>1e+16</upper>
          </limit>
          <dynamics>
            <spring_reference>0</spring_reference>
            <spring_stiffness>0</spring_stiffness>
          </dynamics>
        </axis>
      </joint>
      <link name='l_wheel_right_back'>
        <pose relative_to='j_engine_right_back'>0 0 0 0 -0 0</pose>
        <inertial>
          <pose>-6e-06 0.000159 0.11381 0 -0 0</pose>
          <mass>15</mass>
          <inertia>
            <ixx>0.58617</ixx>
            <ixy>-4.371e-05</ixy>
            <ixz>-4.3139e-06</ixz>
            <iyy>0.58725</iyy>
            <iyz>-5.3239e-05</iyz>
            <izz>0.97459</izz>
          </inertia>
        </inertial>
        <collision name='l_wheel_right_back_collision'>
          <pose>0 0 0 0 -0 0</pose>
          <geometry>
            <mesh>
              <scale>1 1 1</scale>
              <uri>model://meshes/visual/l_wheel_right_back.STL</uri>
            </mesh>
          </geometry>
          <max_contacts>10</max_contacts>
          <surface>
            <contact>
              <ode/>
            </contact>
            <bounce/>
            <friction>
              <torsional>
                <ode/>
              </torsional>
              <ode/>
            </friction>
          </surface>
        </collision>
        <visual name='l_wheel_right_back_visual'>
          <pose>0 0 0 0 -0 0</pose>
          <geometry>
            <mesh>
              <scale>1 1 1</scale>
              <uri>model://meshes/visual/l_wheel_right_back.STL</uri>
            </mesh>
          </geometry>
        </visual>
        <self_collide>0</self_collide>
        <enable_wind>0</enable_wind>
        <kinematic>0</kinematic>
      </link>
      <joint name='j_engine_right_front' type='revolute'>
        <pose relative_to='base_footprint'>0.021624 -0.57853 -0.05133 1.5708 -0 0</pose>
        <parent>base_footprint</parent>
        <child>l_wheel_right_front</child>
        <axis>
          <xyz>0 0 1</xyz>
          <limit>
            <lower>-1e+16</lower>
            <upper>1e+16</upper>
          </limit>
          <dynamics>
            <spring_reference>0</spring_reference>
            <spring_stiffness>0</spring_stiffness>
          </dynamics>
        </axis>
      </joint>
      <link name='l_wheel_right_front'>
        <pose relative_to='j_engine_right_front'>0 0 0 0 -0 0</pose>
        <inertial>
          <pose>-6e-06 0.000159 0.11381 0 -0 0</pose>
          <mass>15</mass>
          <inertia>
            <ixx>0.58617</ixx>
            <ixy>-4.371e-05</ixy>
            <ixz>-4.3139e-06</ixz>
            <iyy>0.58725</iyy>
            <iyz>-5.3239e-05</iyz>
            <izz>0.97459</izz>
          </inertia>
        </inertial>
        <collision name='l_wheel_right_front_collision'>
          <pose>0 0 0 0 -0 0</pose>
          <geometry>
            <mesh>
              <scale>1 1 1</scale>
              <uri>model://meshes/visual/l_wheel_right_front.STL</uri>
            </mesh>
          </geometry>
          <max_contacts>10</max_contacts>
          <surface>
            <contact>
              <ode/>
            </contact>
            <bounce/>
            <friction>
              <torsional>
                <ode/>
              </torsional>
              <ode/>
            </friction>
          </surface>
        </collision>
        <visual name='l_wheel_right_front_visual'>
          <pose>0 0 0 0 -0 0</pose>
          <geometry>
            <mesh>
              <scale>1 1 1</scale>
              <uri>model://meshes/visual/l_wheel_right_front.STL</uri>
            </mesh>
          </geometry>
        </visual>
        <self_collide>0</self_collide>
        <enable_wind>0</enable_wind>
        <kinematic>0</kinematic>
      </link>
      <frame name='j_base_left_back' attached_to='base_link'>
        <pose>-0.58789 0.44933 -0.18225 1.5708 -0 -3.14159</pose>
      </frame>
      <frame name='l_engine_left_back' attached_to='j_base_left_back'/>
      <frame name='j_base_left_front' attached_to='base_link'>
        <pose>0.021624 0.44933 -0.18225 1.5708 -0 -3.14159</pose>
      </frame>
      <frame name='l_engine_left_front' attached_to='j_base_left_front'/>
      <frame name='j_base_right_back' attached_to='base_link'>
        <pose>-0.45797 -0.55765 -0.10997 1.5708 -0 0</pose>
      </frame>
      <frame name='l_engine_right_back' attached_to='j_base_right_back'/>
      <frame name='j_base_right_front' attached_to='base_link'>
        <pose>0.021624 -0.45265 -0.18225 1.5708 -0 0</pose>
      </frame>
      <frame name='l_engine_right_front' attached_to='j_base_right_front'/>
      <frame name='base_footprint_joint' attached_to='base_footprint'>
        <pose>0 0 0.001 0 -0 0</pose>
      </frame>
      <frame name='base_link' attached_to='base_footprint_joint'/>
      <pose>-6.3411 6.95318 0 0 -0 0</pose>
    </model>
  </world>
</sdf>
